<?xml version="1.0"?>

<robot name="head" xmlns:xacro="http://www.ros.org/wiki/xacro">
  <xacro:property name="width" value="0.1" />
  <xacro:property name="height1" value="2" />
  <xacro:property name="mass" value="5" />
  <xacro:property name="rad" value="0.05" />
  <xacro:property name="rad_y" value="0.05" />
  <xacro:property name="rad_z" value="0.08" />
  <xacro:property name="rad_x" value="0.03" />

  <xacro:property name="rad_small" value="0.01" />
  <xacro:include filename="$(find heads)/urdf/materials.xacro" />
  <xacro:include filename="$(find heads)/urdf/head.gazebo" />

  <link name="world"/>


  <link name="torse_link">

    <collision name='collision'>
      <geometry>
        <mesh filename="package://heads/models/torso.dae"/>
      </geometry>
    </collision>

    <visual name='visual'>
      <geometry>
        <mesh filename="package://heads/models/torso.dae"/>
      </geometry>
      <material name="black"/>
    </visual>

    <inertial>
      <origin xyz="0 0 0" />
      <mass value="70.0" />
      <inertia  ixx="1.0" ixy="0.0"  ixz="0.0"  iyy="100.0"  iyz="0.0"  izz="1.0" />
    </inertial>
  </link>

  <joint name="torse_joint" type="fixed">
    <origin xyz="0 0 0.0" rpy="1.57 0 0"/>
    <parent link="world"/>
    <child link="torse_link"/>
  </joint>



  <link name="head_yaw_link">
    <inertial>
      <origin xyz="0.137802209307 0.090396 0.0227196811405" rpy="0 0 0"/>
      <mass value="0.10"/>
      <inertia ixx="0.0" ixy="0.0" ixz="0.0" iyy="0.0" iyz="0.0" izz="0.0"/>
    </inertial>

  </link>

  <joint name="head_yaw_joint" type="revolute">
    <origin xyz="0 1.5 0.0" rpy="0 0 0"/>
    <axis xyz="0 1 0"/>
    <limit effort="1000.0" lower="-0.50" upper="0.5" velocity="0.5"/>
    <parent link="torse_link"/>
    <child link="head_yaw_link"/>
  </joint>


  <link name="head_pitch_link">
    <inertial>
      <origin xyz="0.137802209307 0.090396 0.0227196811405" rpy="0 0 0"/>
      <mass value="0.10"/>
      <inertia ixx="0.0" ixy="0.0" ixz="0.0" iyy="0.0" iyz="0.0" izz="0.0"/>
    </inertial>
  </link>

  <joint name="head_pitch_joint" type="revolute">
    <axis xyz="1 0 0"/>
    <limit effort="1000.0" lower="-0.50" upper="0.5" velocity="0.5"/>
    <parent link="head_yaw_link"/>
    <child link="head_pitch_link"/>
  </joint>


  <link name="head_roll_link">
    <collision>
     <origin xyz="0 -1.5 0" rpy="0 0 0" />
      <geometry>
        <mesh filename="package://heads/models/head/head.dae"/>
      </geometry>
    </collision>

    <visual>
     <origin xyz="0 -1.5 0" rpy="0 0 0" />
      <geometry>
        <mesh filename="package://heads/models/head/head.dae"/>
      </geometry>
      <material name="orange"/>
    </visual>

    <inertial>
      <origin xyz="0 0 0.1" />
      <mass value="0.010" />
      <inertia  ixx="1.0" ixy="0.0"  ixz="0.0"  iyy="100.0"  iyz="0.0"  izz="1.0" />
    </inertial>
  </link>

  <joint name="head_roll_joint" type="revolute">
    <axis xyz="0 0 1"/>
    <limit effort="1000.0" lower="-0.50" upper="0.5" velocity="0.5"/>
    <parent link="head_pitch_link"/>
    <child link="head_roll_link"/>
  </joint>


<link name="left_eye_link">
    <collision>
      <geometry>
	    <sphere radius="${rad_small}"/>
      </geometry>
    </collision>

    <visual>
      <geometry>
	    <sphere radius="${rad_small}"/>
      </geometry>
      <material name="black"/>
    </visual>

    <inertial>
      <origin xyz="0 0 0.1" />
      <mass value="0.10" />
      <inertia  ixx="1.0" ixy="0.0"  ixz="0.0"  iyy="100.0"  iyz="0.0"  izz="1.0" />
    </inertial>
  </link>

  <joint name="left_eye_joint" type="fixed">
    <origin xyz="${rad_x} ${rad_y} ${rad_z}" rpy="0 0 0"/>
    <parent link="head_roll_link"/>
    <child link="left_eye_link"/>
  </joint>


  <link name="left_eye_yaw_link">
    <inertial>
      <origin xyz="0.137802209307 0.090396 0.0227196811405" rpy="0 0 0"/>
      <mass value="0.10"/>
      <inertia ixx="0.0" ixy="0.0" ixz="0.0" iyy="0.0" iyz="0.0" izz="0.0"/>
    </inertial>
  </link>

  <joint name="left_eye_yaw_joint" type="revolute">
    <axis xyz="0 1 0"/>
    <limit effort="1000.0" lower="-0.50" upper="0.5" velocity="0.5"/>
    <parent link="left_eye_link"/>
    <child link="left_eye_yaw_link"/>
  </joint>

  <link name="left_eye_pitch_link">
    <inertial>
      <origin xyz="0.137802209307 0.090396 0.0227196811405" rpy="0 0 0"/>
      <mass value="0.10"/>
      <inertia ixx="0.0" ixy="0.0" ixz="0.0" iyy="0.0" iyz="0.0" izz="0.0"/>
    </inertial>
  </link>

  <joint name="left_eye_pitch_joint" type="revolute">
    <axis xyz="1 0 0"/>
    <limit effort="1000.0" lower="-0.50" upper="0.5" velocity="0.5"/>
    <parent link="left_eye_yaw_link"/>
    <child link="left_eye_pitch_link"/>
  </joint>




  <link name="right_eye_link">
    <collision>
      <geometry>
	    <sphere radius="${rad_small}"/>
      </geometry>
    </collision>

    <visual>
      <geometry>
	    <sphere radius="${rad_small}"/>
      </geometry>
      <material name="black"/>
    </visual>

    <inertial>
      <origin xyz="0 0 0.1" />
      <mass value="0.10" />
      <inertia  ixx="1.0" ixy="0.0"  ixz="0.0"  iyy="100.0"  iyz="0.0"  izz="1.0" />
    </inertial>
  </link>



  <joint name="right_eye_joint" type="fixed">
    <origin xyz="-${rad_x} ${rad_y} ${rad_z}" rpy="0 0 0"/>
    <parent link="head_roll_link"/>
    <child link="right_eye_link"/>
  </joint>


  <link name="right_eye_yaw_link">
    <inertial>
      <origin xyz="0.137802209307 0.090396 0.0227196811405" rpy="0 0 0"/>
      <mass value="0.10"/>
      <inertia ixx="0.0" ixy="0.0" ixz="0.0" iyy="0.0" iyz="0.0" izz="0.0"/>
    </inertial>
  </link>

  <joint name="right_eye_yaw_joint" type="revolute">
    <axis xyz="0 1 0"/>
    <limit effort="1000.0" lower="-0.50" upper="0.5" velocity="0.5"/>
    <parent link="right_eye_link"/>
    <child link="right_eye_yaw_link"/>
  </joint>

  <link name="right_eye_pitch_link">
    <inertial>
      <origin xyz="0.137802209307 0.090396 0.0227196811405" rpy="0 0 0"/>
      <mass value="0.10"/>
      <inertia ixx="0.0" ixy="0.0" ixz="0.0" iyy="0.0" iyz="0.0" izz="0.0"/>
    </inertial>
  </link>

  <joint name="right_eye_pitch_joint" type="revolute">
    <axis xyz="1 0 0"/>
    <limit effort="1000.0" lower="-0.50" upper="0.5" velocity="0.5"/>
    <parent link="right_eye_yaw_link"/>
    <child link="right_eye_pitch_link"/>
  </joint>



  <link name="left_camera_link">
    <collision>
      <geometry>
	    <sphere radius="${rad_small}"/>
      </geometry>
    </collision>

    <visual>
      <geometry>
	    <sphere radius="${rad_small}"/>
      </geometry>
      <material name="black"/>
    </visual>
    <inertial>
      <origin xyz="0 0 0.1" />
      <mass value="0.10" />
      <inertia  ixx="1.0" ixy="0.0"  ixz="0.0"  iyy="100.0"  iyz="0.0"  izz="1.0" />
    </inertial>
  </link>

  <link name="right_camera_link">
    <collision>
      <geometry>
	    <sphere radius="${rad_small}"/>
      </geometry>
    </collision>

    <visual>
      <geometry>
	    <sphere radius="${rad_small}"/>
      </geometry>
      <material name="black"/>
    </visual>
    <inertial>
      <origin xyz="0 0 0.1" />
      <mass value="0.10" />
      <inertia  ixx="1.0" ixy="0.0"  ixz="0.0"  iyy="100.0"  iyz="0.0"  izz="1.0" />
    </inertial>
  </link>


  <joint name="right_camera_joint" type="fixed">
    <origin xyz="0 0 0" rpy="1.57 -1.57 -3.14"/>
    <parent link="right_eye_pitch_link"/>
    <child link="right_camera_link"/>
  </joint>


  <joint name="left_camera_joint" type="fixed">
    <origin xyz="0 0 0" rpy="1.57 -1.57 -3.14"/>
    <parent link="left_eye_pitch_link"/>
    <child link="left_camera_link"/>
  </joint>



  <link name="left_sig_link">
    <inertial>
      <origin xyz="0 0 0" rpy="0 0 0"/>
      <mass value="0.010"/>
      <inertia ixx="0.0" ixy="0.0" ixz="0.0" iyy="0.0" iyz="0.0" izz="0.0"/>
    </inertial>


    <visual name='visual'>
      <geometry>
	    <box size="1 0.01 0.01"/>
      </geometry>
      <material name="black"/>
    </visual>


  </link>

  <joint name="left_sig_joint" type="fixed">
    <origin xyz="0.5 0 0" rpy="0 0 0"/>
    <parent link="left_camera_link"/>
    <child link="left_sig_link"/>
  </joint>



  <link name="right_sig_link">
    <inertial>
      <origin xyz="0 0 0" rpy="0 0 0"/>
      <mass value="0.010"/>
      <inertia ixx="0.0" ixy="0.0" ixz="0.0" iyy="0.0" iyz="0.0" izz="0.0"/>
    </inertial>


    <visual name='visual'>
      <geometry>
	    <box size="1 0.01 0.01"/>
      </geometry>
      <material name="black"/>
    </visual>


  </link>

  <joint name="right_sig_joint" type="fixed">
    <origin xyz="0.5 0 0" rpy="0 0 0"/>
    <parent link="right_camera_link"/>
    <child link="right_sig_link"/>
  </joint>


  <transmission name="head_yaw_joint_tran">
    <type>transmission_interface/SimpleTransmission</type>
    <joint name="head_yaw_joint">
      <hardwareInterface>hardware_interface/PositionJointInterface</hardwareInterface>
    </joint>
    <actuator name="head_yaw_joint_motor">
      <hardwareInterface>hardware_interface/PositionJointInterface</hardwareInterface>
      <mechanicalReduction>1</mechanicalReduction>
    </actuator>
  </transmission>

  <transmission name="head_pitch_joint_tran">
    <type>transmission_interface/SimpleTransmission</type>
    <joint name="head_pitch_joint">
      <hardwareInterface>hardware_interface/PositionJointInterface</hardwareInterface>
    </joint>
    <actuator name="head_pitch_joint_motor">
      <hardwareInterface>hardware_interface/PositionJointInterface</hardwareInterface>
      <mechanicalReduction>1</mechanicalReduction>
    </actuator>
  </transmission>


  <transmission name="head_roll_joint_tran">
    <type>transmission_interface/SimpleTransmission</type>
    <joint name="head_roll_joint">
      <hardwareInterface>hardware_interface/PositionJointInterface</hardwareInterface>
    </joint>
    <actuator name="head_roll_joint_motor">
      <hardwareInterface>hardware_interface/PositionJointInterface</hardwareInterface>
      <mechanicalReduction>1</mechanicalReduction>
    </actuator>
  </transmission>


  <transmission name="left_eye_yaw_joint_tran">
    <type>transmission_interface/SimpleTransmission</type>
    <joint name="left_eye_yaw_joint">
      <hardwareInterface>hardware_interface/PositionJointInterface</hardwareInterface>
    </joint>
    <actuator name="left_eye_yaw_joint_motor">
      <hardwareInterface>hardware_interface/PositionJointInterface</hardwareInterface>
      <mechanicalReduction>1</mechanicalReduction>
    </actuator>
  </transmission>


  <transmission name="left_eye_pitch_joint_tran">
    <type>transmission_interface/SimpleTransmission</type>
    <joint name="left_eye_pitch_joint">
      <hardwareInterface>hardware_interface/PositionJointInterface</hardwareInterface>
    </joint>
    <actuator name="left_eye_pitch_joint_motor">
      <hardwareInterface>hardware_interface/PositionJointInterface</hardwareInterface>
      <mechanicalReduction>1</mechanicalReduction>
    </actuator>
  </transmission>


  <transmission name="right_eye_yaw_joint_tran">
    <type>transmission_interface/SimpleTransmission</type>
    <joint name="right_eye_yaw_joint">
      <hardwareInterface>hardware_interface/PositionJointInterface</hardwareInterface>
    </joint>
    <actuator name="right_eye_yaw_joint_motor">
      <hardwareInterface>hardware_interface/PositionJointInterface</hardwareInterface>
      <mechanicalReduction>1</mechanicalReduction>
    </actuator>
  </transmission>


  <transmission name="right_eye_pitch_joint_tran">
    <type>transmission_interface/SimpleTransmission</type>
    <joint name="right_eye_pitch_joint">
      <hardwareInterface>hardware_interface/PositionJointInterface</hardwareInterface>
    </joint>
    <actuator name="right_eye_pitch_joint">
      <hardwareInterface>hardware_interface/PositionJointInterface</hardwareInterface>
      <mechanicalReduction>1</mechanicalReduction>
    </actuator>
  </transmission>


</robot>
